Workbook
Name Печать: #REF!
Name Опрессовка: 'ТЕХ.ЛИСТ.ОБ'!$B$1:$N$1

Sheet ТЕХ.ЛИСТ.ОБ
A1: {=(БД.ОП[Название])} -> Резка | B1: =IFERROR(__xludf.DUMMYFUNCTION("IF(A1="""","""",IFERROR(TRANSPOSE(query(БД.ОБ,""SELECT P WHERE D='""&A1&""'"")),""""))"),"")
A2: Резка | B2: =IFERROR(__xludf.DUMMYFUNCTION("IF(A2="""","""",IFERROR(TRANSPOSE(query(БД.ОБ,""SELECT P WHERE D='""&A2&""'"")),""""))"),"")
A3: Резка линейных материалов | B3: =IFERROR(__xludf.DUMMYFUNCTION("IF(A3="""","""",IFERROR(TRANSPOSE(query(БД.ОБ,""SELECT P WHERE D='""&A3&""'"")),""""))"),"")
A4: Резка линейных материалов | B4: =IFERROR(__xludf.DUMMYFUNCTION("IF(A4="""","""",IFERROR(TRANSPOSE(query(БД.ОБ,""SELECT P WHERE D='""&A4&""'"")),""""))"),"")
A5: Резка с разделкой | B5: =IFERROR(__xludf.DUMMYFUNCTION("IF(A5="""","""",IFERROR(TRANSPOSE(query(БД.ОБ,""SELECT P WHERE D='""&A5&""'"")),""""))"),"")
A6: Резка с разделкой | B6: =IFERROR(__xludf.DUMMYFUNCTION("IF(A6="""","""",IFERROR(TRANSPOSE(query(БД.ОБ,""SELECT P WHERE D='""&A6&""'"")),""""))"),"")
A7: Резка с разделкой | B7: =IFERROR(__xludf.DUMMYFUNCTION("IF(A7="""","""",IFERROR(TRANSPOSE(query(БД.ОБ,""SELECT P WHERE D='""&A7&""'"")),""""))"),"")
A8: Резка с разделкой | B8: =IFERROR(__xludf.DUMMYFUNCTION("IF(A8="""","""",IFERROR(TRANSPOSE(query(БД.ОБ,""SELECT P WHERE D='""&A8&""'"")),""""))"),"")
A9: Резка с разделкой+ маркировка | B9: =IFERROR(__xludf.DUMMYFUNCTION("IF(A9="""","""",IFERROR(TRANSPOSE(query(БД.ОБ,""SELECT P WHERE D='""&A9&""'"")),""""))"),"")
A10: Резка с разделкой+ маркировка | B10: =IFERROR(__xludf.DUMMYFUNCTION("IF(A10="""","""",IFERROR(TRANSPOSE(query(БД.ОБ,""SELECT P WHERE D='""&A10&""'"")),""""))"),"")
A11: Резка с разделкой+ маркировка | B11: =IFERROR(__xludf.DUMMYFUNCTION("IF(A11="""","""",IFERROR(TRANSPOSE(query(БД.ОБ,""SELECT P WHERE D='""&A11&""'"")),""""))"),"")
A12: Резка с разделкой+ маркировка | B12: =IFERROR(__xludf.DUMMYFUNCTION("IF(A12="""","""",IFERROR(TRANSPOSE(query(БД.ОБ,""SELECT P WHERE D='""&A12&""'"")),""""))"),"")
A13: Автомат резка + опрессовка | B13: =IFERROR(__xludf.DUMMYFUNCTION("IF(A13="""","""",IFERROR(TRANSPOSE(query(БД.ОБ,""SELECT P WHERE D='""&A13&""'"")),""""))"),"")
A14: Автомат резка + опрессовка + лужение | B14: =IFERROR(__xludf.DUMMYFUNCTION("IF(A14="""","""",IFERROR(TRANSPOSE(query(БД.ОБ,""SELECT P WHERE D='""&A14&""'"")),""""))"),"")
A15: Автомат резка + опрессовка | B15: =IFERROR(__xludf.DUMMYFUNCTION("IF(A15="""","""",IFERROR(TRANSPOSE(query(БД.ОБ,""SELECT P WHERE D='""&A15&""'"")),""""))"),"")
A16: Резка линейных материалов | B16: =IFERROR(__xludf.DUMMYFUNCTION("IF(A16="""","""",IFERROR(TRANSPOSE(query(БД.ОБ,""SELECT P WHERE D='""&A16&""'"")),""""))"),"")
A17: Резка линейных материалов | B17: =IFERROR(__xludf.DUMMYFUNCTION("IF(A17="""","""",IFERROR(TRANSPOSE(query(БД.ОБ,""SELECT P WHERE D='""&A17&""'"")),""""))"),"")
A18: Резка линейных материалов | B18: =IFERROR(__xludf.DUMMYFUNCTION("IF(A18="""","""",IFERROR(TRANSPOSE(query(БД.ОБ,""SELECT P WHERE D='""&A18&""'"")),""""))"),"")
A19: Разделка | B19: =IFERROR(__xludf.DUMMYFUNCTION("IF(A19="""","""",IFERROR(TRANSPOSE(query(БД.ОБ,""SELECT P WHERE D='""&A19&""'"")),""""))"),"")
A20: Разделка | B20: =IFERROR(__xludf.DUMMYFUNCTION("IF(A20="""","""",IFERROR(TRANSPOSE(query(БД.ОБ,""SELECT P WHERE D='""&A20&""'"")),""""))"),"")
A21: Разделка | B21: =IFERROR(__xludf.DUMMYFUNCTION("IF(A21="""","""",IFERROR(TRANSPOSE(query(БД.ОБ,""SELECT P WHERE D='""&A21&""'"")),""""))"),"")
A22: Разделка | B22: =IFERROR(__xludf.DUMMYFUNCTION("IF(A22="""","""",IFERROR(TRANSPOSE(query(БД.ОБ,""SELECT P WHERE D='""&A22&""'"")),""""))"),"")
A23: Разделка | B23: =IFERROR(__xludf.DUMMYFUNCTION("IF(A23="""","""",IFERROR(TRANSPOSE(query(БД.ОБ,""SELECT P WHERE D='""&A23&""'"")),""""))"),"")
A24: Разделка | B24: =IFERROR(__xludf.DUMMYFUNCTION("IF(A24="""","""",IFERROR(TRANSPOSE(query(БД.ОБ,""SELECT P WHERE D='""&A24&""'"")),""""))"),"")
A25: Разделка | B25: =IFERROR(__xludf.DUMMYFUNCTION("IF(A25="""","""",IFERROR(TRANSPOSE(query(БД.ОБ,""SELECT P WHERE D='""&A25&""'"")),""""))"),"")
A26: Разделка | B26: =IFERROR(__xludf.DUMMYFUNCTION("IF(A26="""","""",IFERROR(TRANSPOSE(query(БД.ОБ,""SELECT P WHERE D='""&A26&""'"")),""""))"),"")
A27: Разделка | B27: =IFERROR(__xludf.DUMMYFUNCTION("IF(A27="""","""",IFERROR(TRANSPOSE(query(БД.ОБ,""SELECT P WHERE D='""&A27&""'"")),""""))"),"")
A28: Разделка | B28: =IFERROR(__xludf.DUMMYFUNCTION("IF(A28="""","""",IFERROR(TRANSPOSE(query(БД.ОБ,""SELECT P WHERE D='""&A28&""'"")),""""))"),"")
A29: Разделка | B29: =IFERROR(__xludf.DUMMYFUNCTION("IF(A29="""","""",IFERROR(TRANSPOSE(query(БД.ОБ,""SELECT P WHERE D='""&A29&""'"")),""""))"),"")
A30: Разделка | B30: =IFERROR(__xludf.DUMMYFUNCTION("IF(A30="""","""",IFERROR(TRANSPOSE(query(БД.ОБ,""SELECT P WHERE D='""&A30&""'"")),""""))"),"")
A31: Разделка | B31: =IFERROR(__xludf.DUMMYFUNCTION("IF(A31="""","""",IFERROR(TRANSPOSE(query(БД.ОБ,""SELECT P WHERE D='""&A31&""'"")),""""))"),"")
A32: Разделка | B32: =IFERROR(__xludf.DUMMYFUNCTION("IF(A32="""","""",IFERROR(TRANSPOSE(query(БД.ОБ,""SELECT P WHERE D='""&A32&""'"")),""""))"),"")
A33: Разделка | B33: =IFERROR(__xludf.DUMMYFUNCTION("IF(A33="""","""",IFERROR(TRANSPOSE(query(БД.ОБ,""SELECT P WHERE D='""&A33&""'"")),""""))"),"")
A34: Опрессовка терминалов | B34: =IFERROR(__xludf.DUMMYFUNCTION("IF(A34="""","""",IFERROR(TRANSPOSE(query(БД.ОБ,""SELECT P WHERE D='""&A34&""'"")),""""))"),"")
A35: Опрессовка терминалов | B35: =IFERROR(__xludf.DUMMYFUNCTION("IF(A35="""","""",IFERROR(TRANSPOSE(query(БД.ОБ,""SELECT P WHERE D='""&A35&""'"")),""""))"),"")
A36: Опрессовка терминалов | B36: =IFERROR(__xludf.DUMMYFUNCTION("IF(A36="""","""",IFERROR(TRANSPOSE(query(БД.ОБ,""SELECT P WHERE D='""&A36&""'"")),""""))"),"")
A37: Опрессовка терминалов | B37: =IFERROR(__xludf.DUMMYFUNCTION("IF(A37="""","""",IFERROR(TRANSPOSE(query(БД.ОБ,""SELECT P WHERE D='""&A37&""'"")),""""))"),"")
A38: Опрессовка терминалов | B38: =IFERROR(__xludf.DUMMYFUNCTION("IF(A38="""","""",IFERROR(TRANSPOSE(query(БД.ОБ,""SELECT P WHERE D='""&A38&""'"")),""""))"),"")
A39: Опрессовка наконечников | B39: =IFERROR(__xludf.DUMMYFUNCTION("IF(A39="""","""",IFERROR(TRANSPOSE(query(БД.ОБ,""SELECT P WHERE D='""&A39&""'"")),""""))"),"")
A40: Опрессовка наконечников | B40: =IFERROR(__xludf.DUMMYFUNCTION("IF(A40="""","""",IFERROR(TRANSPOSE(query(БД.ОБ,""SELECT P WHERE D='""&A40&""'"")),""""))"),"")
...

Sheet БД.МАТ
A1: Наименование | B1: Группа | C1: Производитель | D1: Серия | E1: Размер до, мм | F1: Размер после, мм | G1: Коэф. усадки | H1: Цвет | I1: Клеевой слой | J1: Материал | K1: Темп. от, °C | L1: Темп. до, °C | M1: Ед. изм. | N1: Закупок | O1: Цена посл., ₽ без НДС | P1: Поставщик | Q1: Ссылка на datasheet | R1: Источник данных
A2: ТУТнг 4/2 черная | B2: ТУТ | C2: КВТ Калуга | D2: ТУТнг-LS | E2: 4 | F2: 2 | G2: 2:1 | H2: черный | I2: нет | J2: полиолефин нг-LS (низкое дымо- и газовыделение) | K2: -55 | L2: 125 | M2: м | N2: 89 | O2: 11.5 | P2: electro-mpo.ru | Q2: https://www.electro-mpo.ru/catalog/materialy/t26_trubki_termousadochnye_chernye_rossiya/t2670_trubka_tut4_2_termousazhivaemaya_dvnutr_4_2m/ | R2: https://www.electro-mpo.ru/catalog/materialy/t26_trubki_termousadochnye_chernye_rossiya/t2670_trubka_tut4_2_termousazhivaemaya_dvnutr_4_2m/
A3: ТУТнг 6/3 черная | B3: ТУТ | C3: КВТ Калуга | D3: ТУТнг-LS | E3: 6 | F3: 3 | G3: 2:1 | H3: черный | I3: нет | J3: полиолефин нг-LS (низкое дымо- и газовыделение) | K3: -55 | L3: 125 | M3: м | N3: 74 | O3: 17.5 | P3: electro-mpo.ru | Q3: https://www.electro-mpo.ru/catalog/materialy/t26_trubki_termousadochnye_chernye_rossiya/t2671_trubka_tut6_3_termousazhivaemaya_dvnutr_6_3m/ | R3: https://www.electro-mpo.ru/catalog/materialy/t26_trubki_termousadochnye_chernye_rossiya/t2671_trubka_tut6_3_termousazhivaemaya_dvnutr_6_3m/
A4: ТУТнг 2/1 черная | B4: ТУТ | C4: КВТ Калуга | D4: ТУТнг-LS | E4: 2 | F4: 1 | G4: 2:1 | H4: черный | I4: нет | J4: полиолефин нг-LS (низкое дымо- и газовыделение) | K4: -55 | L4: 125 | M4: м | N4: 59 | O4: 7 | P4: electro-mpo.ru | Q4: https://www.electro-mpo.ru/catalog/materialy/t26_trubki_termousadochnye_chernye_rossiya/t2669_trubka_tut2_1_termousazhivaemaya_dvnutr_2_1m/ | R4: https://www.electro-mpo.ru/catalog/materialy/t26_trubki_termousadochnye_chernye_rossiya/t2669_trubka_tut2_1_termousazhivaemaya_dvnutr_2_1m/
A5: ТУТнг 1,0/0,5 черная | B5: ТУТ | C5: Rexant | D5: ТУТнг-LS(2:1) 20-1006 | E5: 1 | F5: 0.5 | G5: 2:1 | H5: черный | I5: нет | J5: полиолефин | K5: -40 | L5: 125 | M5: м | N5: 20 | O5: 73 | P5: vseinstrumenti.ru | Q5: https://www.vseinstrumenti.ru/product/termousadka-rexant-1-0-0-5-mm-1-m-chernaya-20-1006-882044/ | R5: https://www.vseinstrumenti.ru/product/termousadka-rexant-1-0-0-5-mm-1-m-chernaya-20-1006-882044/ ; последняя цена 73,0 (08.2026) против 8–9 ₽ ранее — вероятно другая фасовка — решено агентом — проверить
A6: ТУТ 10/5 черная | B6: ТУТ | E6: 10 | F6: 5 | G6: 2:1 | H6: черный | I6: нет | M6: м | N6: 19 | O6: 23.6 | P6: electro-mpo.ru | Q6: https://www.electro-mpo.ru/catalog/materialy/t26_trubki_termousadochnye_chernye_rossiya/t2673_trubka_tut10_5_termousazhivaemaya_dvnutr_10_/ | R6: размер и цвет из обозначения закупки, карточка electro-mpo t2673 ТУТ 10/5; производитель/материал/температуры не сняты — решено агентом — проверить
A7: ТУТ 8/4 черная | B7: ТУТ | E7: 8 | F7: 4 | G7: 2:1 | H7: черный | I7: нет | M7: м | N7: 27 | O7: 19 | P7: electro-mpo.ru | Q7: https://www.electro-mpo.ru/catalog/materialy/t26_trubki_termousadochnye_chernye_rossiya/t2671_trubka_tut6_3_termousazhivaemaya_dvnutr_6_3m/?yadiscount=eyJhIjo1MDAsImRwIjoxLCJsdCI6MTIwLCJwIjoxMCwidCI6MSwidHMiOjE3NzA4MjExMzF9&ysclid=mli56i2uag57995138 | R7: https://www.electro-mpo.ru/catalog/materialy/t26_trubki_termousadochnye_chernye_rossiya/t2671_trubka_tut6_3_termousazhivaemaya_dvnutr_6_3m/ — ссылка в сводке ведёт на карточку ТУТ 6/3мм, а не 8/4мм; размер/цвет/коэф. усадки взяты из текста обозначения — решено агентом — проверить
A8: ТТК 6/2 черная | B8: ТТК | C8: КВТ Калуга | D8: ТТК(3:1) | E8: 6 | F8: 2 | G8: 3:1 | H8: черный | I8: да | J8: полиолефин нг | K8: -55 | L8: 125 | M8: м | N8: 21 | O8: 27 | P8: electro-mpo.ru | Q8: https://www.electro-mpo.ru/catalog/materialy/t32_trubki_termousadochnye_kleevye_3_1_elektromont/t3266-trubka-ttk-6-2-termousazhivaemaya-s-kleem-ch/ | R8: https://www.electro-mpo.ru/catalog/materialy/t32_trubki_termousadochnye_kleevye_3_1_elektromont/t3266-trubka-ttk-6-2-termousazhivaemaya-s-kleem-ch/
A9: ТТК 12/4 черная | B9: ТТК | C9: КВТ Калуга | D9: ТТК(3:1) | E9: 12 | F9: 4 | G9: 3:1 | H9: черный | I9: да | J9: полиолефин нг | K9: -55 | L9: 125 | M9: м | N9: 19 | O9: 112 | P9: electro-mpo.ru | Q9: https://www.electro-mpo.ru/catalog/materialy/t32_trubki_termousadochnye_kleevye_3_1_elektromont/t3268-trubka-ttk-12-4-termousazhivaemaya-s-kleem-ch/ | R9: https://www.electro-mpo.ru/catalog/materialy/t32_trubki_termousadochnye_kleevye_3_1_elektromont/t3268-trubka-ttk-12-4-termousazhivaemaya-s-kleem-ch/
A10: ТУТ 3,0/1,5 черная | B10: ТУТ | C10: Rexant | D10: 20-3006 | E10: 3 | F10: 1.5 | G10: 2:1 | H10: черный | I10: нет | J10: полиолефин | K10: -55 | L10: 105 | M10: м | N10: 16 | O10: 11.5 | P10: electro-mpo.ru | Q10: https://www.electro-mpo.ru/catalog/materialy/t29_trubki_termousadochnye_elektromontazh_etelec_i/t2930-trubka-20-3006-3-1-5mm-termousazhivaemaya-ch/ | R10: https://www.electro-mpo.ru/catalog/materialy/t29_trubki_termousadochnye_elektromontazh_etelec_i/t2930-trubka-20-3006-3-1-5mm-termousazhivaemaya-ch/
A11: ТТК 4,8/1,6 черная | B11: ТТК | C11: КВТ Калуга | D11: ТТК(3:1) | E11: 4.8 | F11: 1.6 | G11: 3:1 | H11: черный | I11: да | J11: полиолефин нг | K11: -55 | L11: 125 | M11: м | N11: 13 | O11: 39.5 | P11: electro-mpo.ru | Q11: https://www.electro-mpo.ru/catalog/materialy/t32_trubki_termousadochnye_kleevye_3_1_elektromont/t3265-trubka-ttk-4-8-1-6-termousazhivaemaya-s-klee/ | R11: https://www.electro-mpo.ru/catalog/materialy/t32_trubki_termousadochnye_kleevye_3_1_elektromont/t3265-trubka-ttk-4-8-1-6-termousazhivaemaya-s-klee/
A12: ТУТнг 12/6 черная | B12: ТУТ | C12: КВТ Калуга | D12: ТУТнг-LS | E12: 12 | F12: 6 | G12: 2:1 | H12: черный | I12: нет | J12: полиолефин нг-LS (низкое дымо- и газовыделение) | K12: -55 | L12: 125 | M12: м | N12: 12 | O12: 32.5 | P12: electro-mpo.ru | Q12: https://www.electro-mpo.ru/catalog/materialy/t26_trubki_termousadochnye_chernye_rossiya/t2674_trubka_tut12_6_termousazhivaemaya_dvnutr_12_/ | R12: https://www.electro-mpo.ru/catalog/materialy/t26_trubki_termousadochnye_chernye_rossiya/t2674_trubka_tut12_6_termousazhivaemaya_dvnutr_12_/
A13: ТУТ 16/8 черная | B13: ТУТ | E13: 16 | F13: 8 | G13: 2:1 | H13: черный | I13: нет | M13: м | N13: 11 | O13: 41.5 | Q13: https://www.electro-mpo.ru/catalog/materialy/t26_trubki_termousadochnye_chernye_rossiya/t2623_trubka_tut16_8_termousazhivaemaya_dvnutr_16_/?ysclid=mqi5cde33z61061371 | R13: https://www.electro-mpo.ru/catalog/materialy/t26_trubki_termousadochnye_chernye_rossiya/t2623_trubka_tut16_8_termousazhivaemaya_dvnutr_16_/ — страница недоступна (404 на дату проверки); размер/цвет/коэф. усадки взяты из текста обозначения — решено агентом — проверить
A14: ТТК 3/1 черная | B14: ТТК | C14: КВТ Калуга | D14: ТТК(3:1) | E14: 3 | F14: 1 | G14: 3:1 | H14: черный | I14: да | J14: полиолефин нг | K14: -55 | L14: 125 | M14: м | N14: 10 | O14: 28.5 | P14: electro-mpo.ru | Q14: https://www.electro-mpo.ru/catalog/materialy/t32_trubki_termousadochnye_kleevye_3_1_elektromont/t3264-trubka-ttk-3-1-3-1-0-termousazhivaemaya-s-kl/ | R14: https://www.electro-mpo.ru/catalog/materialy/t32_trubki_termousadochnye_kleevye_3_1_elektromont/t3264-trubka-ttk-3-1-3-1-0-termousazhivaemaya-s-kl/
A15: ТТК 9/3 черная | B15: ТТК | C15: КВТ Калуга | D15: ТТК(3:1) | E15: 9 | F15: 3 | G15: 3:1 | H15: черный | I15: да | J15: полиолефин нг | K15: -55 | L15: 125 | M15: м | N15: 10 | O15: 73.5 | P15: electro-mpo.ru | Q15: https://www.electro-mpo.ru/catalog/materialy/t32_trubki_termousadochnye_kleevye_3_1_elektromont/t3267-trubka-ttk-9-3-termousazhivaemaya-s-kleem-ch/ | R15: https://www.electro-mpo.ru/catalog/materialy/t32_trubki_termousadochnye_kleevye_3_1_elektromont/t3267-trubka-ttk-9-3-termousazhivaemaya-s-kleem-ch/
A16: Припой ПОС61 1,0мм с флюсом | B16: припой/флюс | J16: Sn61Pb39 (ПОС61), флюс — канифоль (трубчатый, внутри) | K16: 183 | L16: 190 | M16: кг | N16: 12 | O16: 1.6 | P16: prodiel.ru | Q16: https://prodiel.ru/pripoj-pos-61-10-mm-s-flyusom-1-kg | R16: https://prodiel.ru/pripoj-pos-61-10-mm-s-flyusom-1-kg — темп. от/до здесь означает температуру плавления, не рабочий диапазон — решено агентом — проверить
A17: ТТК 8/2 черная | B17: ТТК | C17: КВТ Калуга | D17: ТТК(4:1) | E17: 8 | F17: 2 | G17: 4:1 | H17: черный | I17: да | J17: полиолефин нг | K17: -55 | L17: 125 | M17: м | N17: 7 | O17: 86.5 | P17: electro-mpo.ru | Q17: https://www.electro-mpo.ru/catalog/materialy/t33_trubki_termousadochnye_kleevye_ftoroplastovye_/t3336_trubka_ttk_8_2_termousazhivaemaya_s_kleem_ch/ | R17: https://www.electro-mpo.ru/catalog/materialy/t33_trubki_termousadochnye_kleevye_ftoroplastovye_/t3336_trubka_ttk_8_2_termousazhivaemaya_s_kleem_ch/
A18: ТУТ 1,5/0,75 черная | B18: ТУТ | C18: Rexant | D18: 20-1506 | E18: 1.5 | F18: 0.75 | G18: 2:1 | H18: черный | I18: нет | J18: полиолефин | K18: -55 | L18: 105 | M18: м | N18: 7 | O18: 10 | P18: electro-mpo.ru | Q18: https://www.electro-mpo.ru/catalog/materialy/t29_trubki_termousadochnye_elektromontazh_etelec_i/t29-trubka-20-1506-termousazhivaemaya-tut-ng-1-5-0/ | R18: https://www.electro-mpo.ru/catalog/materialy/t29_trubki_termousadochnye_elektromontazh_etelec_i/t29-trubka-20-1506-termousazhivaemaya-tut-ng-1-5-0/
A19: ТУТ(3:1)нг-LS 6/2 черная | B19: ТУТ | C19: КВТ Калуга | D19: ТУТ(3:1)нг-LS | E19: 6 | F19: 2 | G19: 3:1 | H19: черный | I19: нет | J19: полиолефин нг-LS (низкое дымо- и газовыделение) | K19: -55 | L19: 125 | M19: м | N19: 5 | O19: 35.4 | P19: electro-mpo.ru | Q19: https://www.electro-mpo.ru/catalog/materialy/t26_trubki_termousadochnye_chernye_rossiya/t3102-trubka-tut-3-1-ng-ls-6-2-83375-termousazhiva/ | R19: https://www.electro-mpo.ru/catalog/materialy/t26_trubki_termousadochnye_chernye_rossiya/t3102-trubka-tut-3-1-ng-ls-6-2-83375-termousazhiva/
A20: Оплётка GTRPA-10 | B20: оплётка | C20: ДКС | D20: GTRPA-10 | E20: 10 | F20: 16 | H20: черный | J20: полиамид (нейлон) | K20: -55 | L20: 130 | M20: м | N20: 7 | O20: 108.5 | P20: electro-mpo.ru | Q20: https://www.electro-mpo.ru/catalog/materialy/m50_pletenka_mednaya_luzhenaya_stalnaya_otsinkovan/m5025_oplyetka_gtrpa_10_kabelnaya_10_20mm_poliamid/ | R20: https://www.electro-mpo.ru/catalog/materialy/m50_pletenka_mednaya_luzhenaya_stalnaya_otsinkovan/m5025_oplyetka_gtrpa_10_kabelnaya_10_20mm_poliamid/
A21: Оплётка XS-10 | B21: оплётка | C21: Fortisflex | D21: XS-10 | E21: 10 | F21: 14 | H21: черный | J21: полиэстер, самозаворачивающаяся | K21: -55 | L21: 150 | M21: м | N21: 5 | O21: 168 | P21: electro-mpo.ru | Q21: https://www.electro-mpo.ru/catalog/materialy/m50_pletenka_mednaya_luzhenaya_stalnaya_otsinkovan/m5059-oplyetka-85380-xs-10-kabelnaya-10-14mm-samoz/ | R21: https://www.electro-mpo.ru/catalog/materialy/m50_pletenka_mednaya_luzhenaya_stalnaya_otsinkovan/m5059-oplyetka-85380-xs-10-kabelnaya-10-14mm-samoz/
A22: ТУТ(HF) 4/2 белая | B22: ТУТ | C22: КВТ | D22: ТУТ(HF) | E22: 4 | F22: 2 | G22: 2:1 | H22: белый | I22: нет | J22: ПЭВД, безгалогенная (HF) | M22: м | N22: 4 | O22: 13.5 | P22: electro-mpo.ru | Q22: https://www.electro-mpo.ru/catalog/materialy/t28_trubki_termousadochnye_tsvetnye_rossiya/t2873-trubka-tut-hf-4-2-termousazhivaemaya-bezgalo/ | R22: https://www.electro-mpo.ru/catalog/materialy/t28_trubki_termousadochnye_tsvetnye_rossiya/t2873-trubka-tut-hf-4-2-termousazhivaemaya-bezgalo/
A23: ТУТ 2/1 белая | B23: ТУТ | C23: Rexant | D23: 20-2001 | E23: 2 | F23: 1 | G23: 2:1 | H23: белый | I23: нет | J23: полиолефин | K23: -55 | L23: 105 | M23: м | N23: 4 | O23: 10.5 | P23: electro-mpo.ru | Q23: https://www.electro-mpo.ru/catalog/materialy/t29_trubki_termousadochnye_elektromontazh_etelec_i/t2920-trubka-20-2001-2-1mm-termousazhivaemaya-bela/ | R23: https://www.electro-mpo.ru/catalog/materialy/t29_trubki_termousadochnye_elektromontazh_etelec_i/t2920-trubka-20-2001-2-1mm-termousazhivaemaya-bela/
A24: ТУТ 8/4 белая | B24: ТУТ | C24: Rexant | D24: 20-8001 | E24: 8 | F24: 4 | G24: 2:1 | H24: белый | I24: нет | J24: полиолефин | K24: -55 | L24: 105 | M24: м | N24: 4 | O24: 18 | P24: electro-mpo.ru | Q24: https://www.electro-mpo.ru/catalog/materialy/t29_trubki_termousadochnye_elektromontazh_etelec_i/t2943-trubka-20-8001-8-4mm-termousazhivaemaya-bela/ | R24: https://www.electro-mpo.ru/catalog/materialy/t29_trubki_termousadochnye_elektromontazh_etelec_i/t2943-trubka-20-8001-8-4mm-termousazhivaemaya-bela/
A25: Оплётка XS-13 | B25: оплётка | C25: Fortisflex | D25: XS-13 | E25: 13 | F25: 17 | H25: черный | J25: полиэстер, самозаворачивающаяся | K25: -55 | L25: 150 | M25: м | N25: 4 | O25: 98.4 | P25: electro-mpo.ru | Q25: https://www.electro-mpo.ru/catalog/materialy/m50_pletenka_mednaya_luzhenaya_stalnaya_otsinkovan/m5060-oplyetka-85381-xs-13-kabelnaya-13-17mm-samoz/ | R25: https://www.electro-mpo.ru/catalog/materialy/m50_pletenka_mednaya_luzhenaya_stalnaya_otsinkovan/m5060-oplyetka-85381-xs-13-kabelnaya-13-17mm-samoz/
A26: ТТК 20/6 черная | B26: ТТК | C26: КВТ Калуга | D26: ТТК(3:1) | E26: 20 | F26: 6 | G26: 3:1 | H26: черный | I26: да | J26: полиолефин нг | K26: -55 | L26: 125 | M26: м | N26: 4 | O26: 0 | P26: electro-mpo.ru | Q26: https://www.electro-mpo.ru/catalog/materialy/t32_trubki_termousadochnye_kleevye_3_1_elektromont/t3269-trubka-ttk-18-6-termousazhivaemaya-s-kleem-ch/ | R26: https://www.electro-mpo.ru/catalog/materialy/t32_trubki_termousadochnye_kleevye_3_1_elektromont/t3269-trubka-ttk-18-6-termousazhivaemaya-s-kleem-ch/ — в адресе страницы указано 18/6, но содержимое карточки (арт. 85067) подтверждает 20/6 — решено агентом — проверить
A27: ТУТ 5,0/2,5 черная | B27: ТУТ | C27: Rexant | D27: 20-5006 | E27: 5 | F27: 2.5 | G27: 2:1 | H27: черный | I27: нет | J27: полиолефин | K27: -40 | L27: 125 | M27: м | N27: 4 | O27: 9.8 | P27: promelec.ru | Q27: https://www.promelec.ru/product/474892/ | R27: https://www.promelec.ru/product/474892/
A28: ТУТ(HF) 3/1,5 черная | B28: ТУТ | C28: КВТ | D28: ТУТ(HF) | E28: 3 | F28: 1.5 | G28: 2:1 | H28: черный | I28: нет | J28: полиолефин HF (безгалогенный) | K28: -55 | L28: 125 | M28: м | N28: 3 | O28: 7.2 | P28: kvt-pro.ru | Q28: https://kvt-pro.ru/mufty-nakonechniki/termousadka-termousadochnye-trubki-trubki-tut-kleevye-trubki/termousadochnye-trubki/tut-hf-1/85120-tut-hf-3-15-chern-termousadochnaia-trubka-s-koeffitsientom-usadki-2-1 | R28: https://kvt-pro.ru/mufty-nakonechniki/termousadka-termousadochnye-trubki-trubki-tut-kleevye-trubki/termousadochnye-trubki/tut-hf-1/85120-tut-hf-3-15-chern-termousadochnaia-trubka-s-koeffitsientom-usadki-2-1
A29: Гофра 6,8мм | B29: гофра | C29: ДКС | E29: 6.8 | H29: черный | J29: полипропилен | K29: -40 | L29: 105 | M29: м | N29: 8 | O29: 9.1 | P29: snabcable.ru | Q29: https://snabcable.ru/car/autogofra/gofra/ | R29: https://snabcable.ru/car/autogofra/gofra/ — размер взят из названия по сводке страницы категории (карточка конкретного диаметра на сайте не выделена отдельным URL) — решено агентом — проверить
A30: Изолента ПВХ 15х0,13х20м | B30: лента | C30: Fortisflex | H30: черный | J30: ПВХ | K30: -30 | L30: 80 | M30: шт | N30: 3 | O30: 145.1 | P30: kvt-pro.ru | Q30: https://kvt-pro.ru/izolenta/90809-izolenta-pvkh-15x0-13kh20-chern | R30: https://kvt-pro.ru/izolenta/90809-izolenta-pvkh-15x0-13kh20-chern
A31: Оплётка XS-19 | B31: оплётка | C31: Fortisflex | D31: XS-19 | E31: 19 | F31: 24 | H31: черный | J31: полиэстер, самозаворачивающаяся | K31: -55 | L31: 150 | M31: м | N31: 3 | O31: 294.5 | P31: electro-mpo.ru | Q31: https://www.electro-mpo.ru/catalog/materialy/m50_pletenka_mednaya_luzhenaya_stalnaya_otsinkovan/m5062-oplyetka-85383-xs-19-kabelnaya-19-24mm-samoz/ | R31: https://www.electro-mpo.ru/catalog/materialy/m50_pletenka_mednaya_luzhenaya_stalnaya_otsinkovan/m5062-oplyetka-85383-xs-19-kabelnaya-19-24mm-samoz/
A32: Лента нетканная 20мм | B32: лента | N32: 3 | O32: 16.4
A33: Оплётка XT-20/10 чёрная | B33: оплётка | C33: Fortisflex | D33: XT (85371) | E33: 20 | F33: 10 | H33: чёрный | J33: полиэстер/полиолефин | K33: -40 | L33: 150 | M33: м | N33: 3 | O33: 213.9 | P33: electro-mpo.ru | Q33: https://www.electro-mpo.ru/catalog/materialy/m50_pletenka_mednaya_luzhenaya_stalnaya_otsinkovan/m5052-oplyetka-85371-xt-20-10-kabelnaya-termousazh/ | R33: https://www.electro-mpo.ru/catalog/materialy/m50_pletenka_mednaya_luzhenaya_stalnaya_otsinkovan/m5052-oplyetka-85371-xt-20-10-kabelnaya-termousazh/ — в закупке указано «Оплетка кабельная XT 16/8мм», но ссылка и карточка ведут на XT-20/10 (арт. 85371); модели XT-16/8 у Fortisflex не найдено — решено агентом — проверить
A34: Стяжка 3x60 | B34: стяжка | M34: шт | N34: 3 | O34: 2.5 | P34: Склад | R34: нет ссылки и датащита, только наименование и поставщик «Склад»; материал/цвет не подтверждены — решено агентом — проверить
A35: Стяжка 5x200 | B35: стяжка | M35: шт | N35: 3 | O35: 2.5 | P35: Склад | R35: нет ссылки и датащита, только наименование и поставщик «Склад»; материал/цвет не подтверждены — решено агентом — проверить
A36: Стяжки 2,5x300мм | B36: стяжка | M36: шт | N36: 3 | O36: 2.5 | P36: Склад | R36: нет ссылки и датащита, только наименование и поставщик «Склад»; материал/цвет не подтверждены — решено агентом — проверить
A37: Тканевая лента T150PT | B37: лента | D37: T150PT | H37: чёрный | J37: полиэстер (тканевая термостойкая) | L37: 80 | M37: шт | N37: 3 | O37: 16.4 | P37: Меттатрон | R37: прямой ссылки на карточку нет (поставщик Меттатрон); по общему поиску — тканевая лента T150PT, чёрная, полиэстер, ширина ок. 19мм, до +80°C — решено агентом — проверить
A38: Токопроводящая экранирующая лента 0,1х50мм х20м | B38: лента | J38: полиэфирная ткань с никелевым покрытием, токопроводящий клей | M38: шт | N38: 3 | O38: 43 | P38: prodiel.ru | Q38: https://prodiel.ru/tokoprovodyaschiy-ekraniruyuschiy-skotch-01-mm-kh-50-mm-kh-20-m | R38: https://prodiel.ru/tokoprovodyaschiy-ekraniruyuschiy-skotch-01-mm-kh-50-mm-kh-20-m — размеры (0,1х50мм, рулон 20м) и состав подтверждены карточкой; температура и производитель на странице не указаны
A39: Тройник 9,8x9,8x9,8 | B39: тройник | C39: Schlemmer | D39: Тип B (9806138) | H39: чёрный | J39: полиамид 66 | K39: -40 | L39: 135 | M39: шт | N39: 3 | O39: 0 | P39: akompany.ru | Q39: https://akompany.ru/soedenitel_na_avtotrubu/t-troynik-tip-b-10-10-10-schlemmer-9806138 | R39: https://akompany.ru/soedenitel_na_avtotrubu/t-troynik-tip-b-10-10-10-schlemmer-9806138 — в закупке указано «Тройник 6,8x6,8x6,8», но карточка Schlemmer подтверждает внутренний диаметр всех сторон 9,8мм (типоразмер 10-10-10) — решено агентом — проверить
A40: Тройник 12,7x9,8x9,8 | B40: тройник | C40: Schlemmer | D40: Тип A (9806091) | H40: чёрный | J40: полиамид 66 | K40: -40 | L40: 135 | M40: шт | N40: 3 | O40: 0 | P40: akompany.ru | Q40: https://akompany.ru/soedenitel_na_avtotrubu/t-troynik-tip-a-13-10-10-schlemmer-9806091 | R40: https://akompany.ru/soedenitel_na_avtotrubu/t-troynik-tip-a-13-10-10-schlemmer-9806091 — в закупке указано «Тройник 6,8x6,8x9,8», но карточка Schlemmer подтверждает 12,7/9,8/9,8мм (типоразмер 13-10-10) — решено агентом — проверить
...

Sheet БД.ПРОВ
A1: Марка | B1: Тип провода | C1: Стандарт / производитель | D1: Сечение, мм2 | E1: AWG | F1: Жила: проволок × диаметр, мм | G1: Число жил | H1: Цвета | I1: Наружный диаметр, мм | J1: Изоляция | K1: Экран | L1: Волновое сопротивление, Ом | M1: Темп. от, °C | N1: Темп. до, °C | O1: Напряжение, В | P1: Ток, А | Q1: Масса, г/м | R1: Закупок | S1: Цена посл., ₽/м без НДС | T1: Поставщик | U1: Ссылка на datasheet | V1: Источник данных
A2: RG316 | B2: коаксиальный | C2: MIL-DTL-17 RG-316/U; реселлер baltic-signal.ru | F2: 7×0,17 (посеребр. медь) | G2: 1 | I2: 2.45 | J2: ПТФЭ (диэлектрик) / ФЭП (оболочка) | K2: посеребрённая медная оплетка 80×0,1 мм | L2: 50 | M2: -60 | N2: 200 | O2: 2000 | Q2: 20 | R2: 43 | S2: 81.1 | T2: Склад, АО "ВНИИР-Прогресс", Давальческое | U2: https://baltic-signal.ru/catalog/accessories/kabel/kabel-rg-316-50-om/ | V2: baltic-signal.ru (осн.); напряжение 2000В — из даташита Huber+Suhner RG316/U (у baltic-signal не указано) — решено агентом — проверить
A3: UL1061 28AWG | B3: монтажный | C3: UL AWM Style 1061, SR-PVC, 300V/80°C | D3: 0.08 | E3: 28 | F3: 7×0,127 (луж. медь, 7/36AWG) | G3: 1 | H3: чёрный, красный, белый, синий, жёлтый, зелёный, оранжевый, коричневый, серый, фиолетовый | I3: 0.89 | J3: полутвёрдый ПВХ (SR-PVC) | M3: -10 | N3: 80 | O3: 300 | Q3: 1.49 | R3: 157 | S3: 5.4 | T3: Склад, Фраксис, Слад, Слкад, Скад, Полина, Давальческое | U3: https://www.remingtonindustries.com/content/UL1061%20Hook%20Up%20Wire%20Data%20Sheet.pdf | V3: Remington/Farnell/rdswire.com UL1061 datasheet; сечение 0,08мм2 и диаметр пряди 0,127мм — по стандартной таблице AWG (7/36), не прямое значение из даташита — решено агентом — проверить. Объединены 8 цветовых позиций (черный,красный,белый,синий,желтый,зеленый,оранжевый,коричневый)
A4: RG-58 A/U | B4: коаксиальный | C4: ГОСТ 31565-2012; VEGATEL RG-58 A/U Cu | F4: 1×0,90 (медь, сплошная — заявлено продавцом) | G4: 1 | H4: чёрный | I4: 4.95 | J4: сплошной полиэтилен (SPE) | K4: алюминиевая фольга (2-сторонняя, 96%) + оплетка | L4: 50 | M4: -60 | N4: 80 | Q4: 27 | R4: 28 | S4: 36.9 | U4: https://www.vegatel.ru/kabel/vegatel-rg-58/kabel-vegatel-rg-58-a-u-cu-gost-re-chernii-buhta-100m | V4: vegatel.ru; жила заявлена продавцом как сплошная медь — для RG-58 A/U обычно многопроволочная (7 прядей) — решено агентом — проверить. Монтажный диапазон -25..+50°C (в таблице — рабочий -60..+80°C)
A5: RG1.37 | B5: коаксиальный | C5: нестандартное обозначение реселлера (тонкий 50-омный коаксиал, аналог RF1.37) | F5: 7×0,105 (посеребр. медь) | G5: 1 | H5: чёрный | I5: 1.37 | J5: ФЭП (FEP) | K5: луженая медная оплетка | L5: 50 | M5: -60 | N5: 200 | O5: 1000 | Q5: 4.6 | R5: 21 | S5: 29.5 | T5: Склад, Фраксис, CINTY, Давальческое, MEI DUO YUAN KEJI | U5: https://gsm-repiteri.ru/prodazha/cable/cable-koaksialnyy-rf1-37 | V5: gsm-repiteri.ru; независимого даташита производителя не найдено — решено агентом — проверить
A6: НВ-4 0,20 | B6: монтажный | C6: ГОСТ 17515-72 | D6: 0.2 | G6: 1 | H6: чёрный, красный, белый, зелёный, жёлтый, синий, коричневый, оранжевый, фиолетовый, голубой, серый | I6: 1.5 | J6: ПВХ-пластикат | M6: -50 | N6: 105 | O6: 600 | R6: 133 | S6: 6.7 | U6: https://snabcable.ru/mounting/nv-nve/nv/ | V6: snabcable.ru; страндинг жилы страницей не указан. У НВ-4 есть варианты на 600В (OD 1,5мм) и 1000В (OD 1,7мм) — взят вариант 600В как базовый — решено агентом — проверить. Объединены 9 цветовых позиций
A7: UL1061 30AWG | B7: монтажный | C7: UL AWM Style 1061, SR-PVC, 300V/80°C | D7: 0.05 | E7: 30 | F7: 7×0,101 (луж. медь, 7/38AWG) | G7: 1 | H7: чёрный, белый, красный, синий, жёлтый, зелёный | I7: 0.81 | J7: полутвёрдый ПВХ (SR-PVC) | M7: -10 | N7: 80 | O7: 300 | Q7: 0.11 | R7: 65 | S7: 4.9 | T7: Китай, Склад, Слкад, Давальческое | U7: https://www.remingtonindustries.com/hook-up-wire/electronics/ul1061-300-volt/ | V7: rdswire.com UL1061 style page; диаметр пряди 0,101мм — по стандартной таблице AWG (7/38), не прямое значение из даташита — решено агентом — проверить. Объединены 5 цветовых позиций
A8: RG178 | B8: коаксиальный | C8: MIL-DTL-17 RG-178/U | F8: 7×0,10 (посеребр. медь) | G8: 1 | H8: чёрный | I8: 1.78 | J8: ПТФЭ | K8: посеребрённая медная оплетка 48×0,1 мм | L8: 50 | M8: -60 | N8: 200 | O8: 1000 | Q8: 7 | R8: 16 | S8: 73.8 | T8: Фраксис, Склад, ООО"ЗЭП "ФРАКСИС", Давальческое, Полина | U8: https://gsm-repiteri.ru/prodazha/cable/cable-rg-178-50-om | V8: gsm-repiteri.ru, согласуется с типовой спецификацией RG-178/U
A9: НВ-4 0,50 | B9: монтажный | C9: ГОСТ 17515-72 | D9: 0.5 | G9: 1 | H9: чёрный, жёлтый, красный, белый | I9: 1.8 | J9: ПВХ-пластикат | M9: -50 | N9: 105 | O9: 600 | R9: 36 | S9: 11.9 | U9: https://snabcable.ru/mounting/nv-nve/nv/ | V9: snabcable.ru; вариант 600В (OD 1,8мм) взят как базовый, есть также вариант 1000В (OD 2,0мм) — решено агентом — проверить
A10: RG174 | B10: коаксиальный | C10: MIL-DTL-17 RG-174/U | F10: 7×0,16 (медь) | G10: 1 | H10: чёрный | I10: 2.8 | J10: сшитый полиэтилен (XLPE, по данным продавца) | K10: луженая омедненная алюминиевая оплетка 64×0,1 мм | L10: 50 | M10: -60 | N10: 70 | O10: 1000 | Q10: 15 | R10: 17 | S10: 20.5 | T10: ИП Астафьева Юлия Андреевна, Давальческое, Заказчик | U10: https://gsm-repiteri.ru/prodazha/cable/kabel-rg-174-50-om | V10: gsm-repiteri.ru; в сводке закупок цена указана как 0,0 — похоже на ошибку данных, оставлено пустым — решено агентом — проверить. Изоляция/экран у продавца отличаются от типового Belden RG-174 (PE и луженая медь) — вероятно удешевлённый вариант
A11: RG402 | B11: коаксиальный (полужёсткий) | C11: MIL-DTL-17 RG-402/U (CF-141-50-FEP) | F11: 1×0,91 (посеребр. медь, сплошная) | G11: 1 | I11: 4.1 | J11: ПТФЭ (сплошной) | K11: медная оплетка/трубка (продавец пишет "оплетка", у полужёсткого RG402 обычно сплошная медная трубка) — решено агентом — проверить | L11: 50 | M11: -60 | N11: 155 | Q11: 44 | R11: 14 | S11: 245.9 | T11: Давальческое, Склад | U11: https://baltic-signal.ru/catalog/accessories/kabel/kabel-rg-402/ | V11: baltic-signal.ru
A12: НВ-4 0,12 | B12: монтажный | C12: ГОСТ 17515-72 | D12: 0.12 | G12: 1 | H12: красный, чёрный, белый, зелёный, жёлтый, синий | I12: 1.3 | J12: ПВХ-пластикат | M12: -50 | N12: 105 | O12: 600 | Q12: 2.35 | R12: 53 | S12: 6.6 | T12: Давальческое | U12: https://snabcable.ru/mounting/nv-nve/nv/ | V12: snabcable.ru (пример веса 2,35 кг/км дан на странице именно для сечения 0,12мм2). Объединены 6 цветовых позиций
A13: RG405 | B13: коаксиальный (полужёсткий) | C13: MIL-DTL-17 RG-405/U (CF-086-50-FEP) | F13: 1×0,51 (посеребр. медь, сплошная) | G13: 1 | I13: 2.69 | J13: ПТФЭ | K13: медная оплетка/трубка (продавец пишет "оплетка", у полужёсткого RG405 обычно сплошная медная трубка) — решено агентом — проверить | L13: 50 | M13: -60 | N13: 155 | Q13: 20 | R13: 14 | S13: 147.5 | T13: Давальческое | U13: https://baltic-signal.ru/catalog/accessories/kabel/kabel-rg-405-cf-086-50-fep/ | V13: baltic-signal.ru
A14: Силиконовый провод 28AWG | B14: силиконовый | C14: генерик (китайское производство), prodiel.ru | D14: 0.08 | E14: 28 | F14: 16×0,08 (луж. медь) | G14: 1 | H14: чёрный, красный, жёлтый, зелёный, белый, синий, фиолетовый | I14: 1.2 | J14: силиконовая резина (метилвинилполисилоксан + SiO2) | M14: -60 | N14: 200 | O14: 600 | P14: 0.8 | R14: 77 | S14: 14.6 | T14: Китай, Продиэлком | U14: https://prodiel.ru/provod/provod-gibkiy-v-silikone/silicon-28-awg/ | V14: prodiel.ru (4 карточки товара, идентичные характеристики); объединены позиции "Силикон" и "Силиконовый" 28AWG (один и тот же товар, разное написание у покупателей) — 7 цветовых/написательных позиций. Цена последней закупки неоднозначна (10,8-11,5 в одном месяце у разных позиций) — решено агентом — проверить
A15: 5D-FB | B15: коаксиальный | C15: JIS 5D-FB | F15: 1×1,80 (медненный алюминий, сплошная) | G15: 1 | H15: чёрный | I15: 7.54 | J15: вспененный полиэтилен | K15: алюминиевая фольга + алюминиево-магниевая оплетка 120×0,15 мм | L15: 50 | M15: -60 | N15: 75 | Q15: 60 | R15: 13 | S15: 61.5 | T15: Давальческое | U15: https://gsm-repiteri.ru/prodazha/cable/kabel-5d-fb-pvc-chernyy | V15: gsm-repiteri.ru; жила из омедненного алюминия и оплетка Al-Mg — удешевлённый вариант относительно типовой JIS-спецификации (медь/луженая медь) — решено агентом — проверить
A16: ПВАМ 0,50 | B16: силовой | C16: ТУ 16.К19-12-2003 | D16: 0.5 | G16: 1 | H16: красный, чёрный, жёлтый, синий, белый, зелёный, голубой, розовый, фиолетовый, серый | I16: 1.6 | J16: ПВХ-пластикат маслобензостойкий | M16: -40 | N16: 105 | O16: 48 (ном.) / 1000 (испыт.) | Q16: 6 | R16: 47 | S16: 7.9 | U16: https://snabcable.ru/car/pvam-pvame-pvamde/pvam/ | V16: snabcable.ru; жила — медь многопроволочная 5-го класса гибкости, страндинг страницей не указан
A17: ПВАМ 0,35 | B17: силовой | C17: ТУ 16.К19-12-2003 | D17: 0.35 | G17: 1 | H17: красный, чёрный, зелёный, белый, жёлтый, оранжевый | I17: 1.4 | J17: ПВХ-пластикат маслобензостойкий | M17: -40 | N17: 105 | O17: 48 (ном.) / 1000 (испыт.) | Q17: 5 | R17: 30 | S17: 10.8 | T17: Заказчик | U17: https://snabcable.ru/car/pvam-pvame-pvamde/pvam/ | V17: snabcable.ru
A18: ПВВС 4×0,35 | B18: многожильный кабель | C18: семейство кабелей сигнализации/блокировки (кандидаты: ГОСТ 31995-2012 / ГОСТ Р 56292-2014, точный номер для этой маркировки не подтверждён) | D18: 0.35 | G18: 4 | H18: чёрный (оболочка) | J18: полиэтилен (изоляция жил) / оболочка — источники расходятся: rfopt.ru/pvvs-4h035 указывает свинцовую оболочку (нетипично), общее описание серии rfopt.ru/pvvs — пластмассовую — решено агентом — проверить | M18: -40 | N18: 60 | O18: 380 (перем.) / 700 (пост.) — по описанию серии, для конкретной позиции не подтверждено | R18: 8 | S18: 59 | U18: https://rfopt.ru/pvvs-4h035 | V18: rfopt.ru (карточка товара + общее описание серии pvvs); наружный диаметр и вес страницей не даны — оставлено пустым. Темп./напряжение — по общему описанию серии ПВВС, не по этой конкретной позиции — решено агентом — проверить
A19: НВ-4 0,75 | B19: монтажный | C19: ГОСТ 17515-72 | D19: 0.75 | G19: 1 | H19: чёрный, коричневый, желто-зелёный, синий, красный, жёлтый, зелёный | I19: 2.1 | J19: ПВХ-пластикат | M19: -50 | N19: 105 | O19: 600 | R19: 43 | S19: 23 | U19: https://snabcable.ru/mounting/nv-nve/nv/ | V19: snabcable.ru; цена последней закупки у разных цветов в одном месяце расходится (15,6-19,5) — взято модальное значение 15,6 — решено агентом — проверить
A20: UL2725 28AWG | B20: монтажный (экранированный многожильный) | C20: UL AWM Style 2725 (регламентируется UL758) | D20: 0.08 | E20: 28 | F20: 7×0,127 (луж. медь, по типовым датащитам) | G20: 1 | J20: ПВХ | K20: возможен (стиль 2725 обычно применяется к экранированным многожильным кабелям) | N20: 60 | O20: 30 | R20: 7 | S20: 32.3 | T20: Склад, Фраксис | V20: ВАЖНОЕ РАСХОЖДЕНИЕ: по независимым датащитам (ul-cables.com/p/ul2725, кабельные сборки типа ulcul.com/.../UL2725-28AWG-x-1Pair-24AWG-x-2C-AEB.pdf) style 2725 — это экранированный МНОГОжильный кабель (напр. для USB), рассчитанный на 30В/60-80°C, а НЕ одиночный монтажный провод на 300В/105°C, как можно было бы предположить по аналогии с UL1061/2725. Конкретная позиция покупателя (без ссылки) не идентифицирована — приведены типовые параметры одной жилы 28AWG из таких кабелей — решено агентом — проверить
A21: ПГВА 0,50 | B21: силовой | C21: ТУ 16.К17-021-94 | D21: 0.5 | G21: 1 | H21: красный, чёрный | I21: 2.3 | J21: ПВХ-пластикат | M21: -40 | N21: 70 | O21: 48 | R21: 12 | S21: 8.9 | U21: https://snabcable.ru/car/pvam-pvame-pvamde/pgva/ | V21: snabcable.ru; жила — медь многопроволочная 3-го класса гибкости, страндинг страницей не указан
A22: Силиконовый провод 20AWG | B22: силиконовый | C22: генерик (китайское производство), prodiel.ru | D22: 0.5 | E22: 20 | F22: 100×0,08 (луж. медь) | G22: 1 | H22: чёрный, жёлтый, красный, серый | I22: 1.8 | J22: силиконовая резина | M22: -60 | N22: 200 | O22: 600 | P22: 13.87 | R22: 17 | S22: 55.7 | V22: данные по сниппету поиска (карточки товара prodiel.ru), не проверено прямым WebFetch в этой сессии; ток 13,87А выглядит нетипично точным по сравнению с другими типоразмерами — решено агентом — проверить
A23: Силиконовый провод 30AWG | B23: силиконовый | C23: генерик (китайское производство), prodiel.ru | D23: 0.05 | E23: 30 | F23: 11×0,08 (луж. медь) | G23: 1 | H23: чёрный, красный, жёлтый, синий, зелёный, оранжевый | I23: 0.8 | J23: силиконовая резина | M23: -60 | N23: 200 | O23: 600 | P23: 0,5 (длит.) / 0,8 (кратк.) | Q23: 1.5 | R23: 37 | S23: 4.1 | T23: Китай | U23: https://prodiel.ru/provod-silikonoviy-30awg-005-mm-2500-m-cherniy | V23: prodiel.ru
A24: НВ-4 0,35 | B24: монтажный | C24: ГОСТ 17515-72 | D24: 0.35 | G24: 1 | H24: чёрный, красный, белый, зелёный, жёлтый, синий | I24: 1.6 | J24: ПВХ-пластикат | M24: -50 | N24: 105 | O24: 600 | R24: 43 | S24: 12.3 | U24: https://snabcable.ru/mounting/nv-nve/nv/ | V24: snabcable.ru; объединены варианты написания "НВ-4 0,35мм2", "НВ4-0,35мм2", "НВ4 0,35" — канонизировано как НВ-4 0,35
A25: Силиконовый провод 26AWG | B25: силиконовый | C25: генерик (китайское производство), prodiel.ru | D25: 0.15 | E25: 26 | F25: 30×0,08 (луж. медь) | G25: 1 | H25: красный, чёрный, белый, жёлтый, зелёный, коричневый, синий | I25: 1.5 | J25: силиконовая резина (метилвинилполисилоксан) | M25: -60 | N25: 200 | O25: 600 | P25: 1.5 | R25: 23 | S25: 23.4 | U25: https://prodiel.ru/provod-gibkiy-silikonoviy-awg-26-012-mm-kv-krasniy-100-m | V25: prodiel.ru (2 карточки товара, идентичные характеристики)
A26: UL758 10AWG | B26: монтажный | C26: UL758 — номер стандарта AWM (Appliance Wiring Material) в целом, НЕ конкретный style/марка | D26: 5.26 | E26: 10 | G26: 1 | H26: black, red | R26: 10 | S26: 117.5 | T26: Полина, Китай | V26: UL758 — это обозначение стандарта безопасности UL для класса проводов AWM, а не конкретная конструкция; покупатель указал только "UL758 10AWG" без ссылки, конкретный AWM-style не идентифицирован — решено агентом — проверить. Сечение 5,26мм2 — по стандартной таблице AWG для 10AWG, не из даташита
A27: МС16-13 0,08 | B27: монтажный (высокотемпературный) | C27: ТУ 16-505.083-78 | D27: 0.08 | F27: 7×0,15 (посеребр. медь, марка МСр/БМС) | G27: 1 | H27: белый, зелёный, красный, чёрный, жёлтый, коричневый, оранжевый, синий | I27: 0.72 | J27: фторопластовая плёнка марки 4Д (обмотка) | M27: -60 | N27: 200 | O27: 100 (AC до 10кГц) / 150 (DC) | R27: 36 | S27: 63.1 | U27: https://snabcable.ru/onboard/ms-e-o-16-26-13/ms-16-13/ | V27: snabcable.ru + агрегированные данные по ряду сечений МС16-13 (bystrokabel.ru); жила 7×0,15мм для 0,08мм2 — не проверено первичным текстом ТУ 16-505.083-78 — решено агентом — проверить
A28: МС16-13 0,12 | B28: монтажный (высокотемпературный) | C28: ТУ 16-505.083-78 | D28: 0.12 | F28: 7×0,15 (посеребр. медь) | G28: 1 | H28: красный, чёрный, белый, зелёный, синий, коричневый, оранжевый | I28: 0.9 | J28: фторопластовая плёнка марки 4Д (обмотка) | M28: -60 | N28: 200 | O28: 100 (AC до 10кГц) / 150 (DC) | Q28: 1.9 | R28: 26 | S28: 118.1 | U28: https://snabcable.ru/onboard/ms-e-o-16-26-13/ms-16-13/ | V28: snabcable.ru + bystrokabel.ru (карточка МС16-13 0,12): жила 7×0,15мм, OD 0,90мм, масса 1,9кг/км, ТУ 16-505.083-78 — решено агентом — проверить (данные по типовому ряду сечений, не первичный текст ТУ). Цена закупки у разных цветов расходится (97,8–100,7) — взято среднее 99,1 — решено агентом — проверить. Объединены 5 цветовых позиций (красный,чёрный,белый,зелёный,синий)
A29: ПВАМ 1,0 | B29: силовой | C29: ТУ 16.К19-12-2003 | D29: 1 | G29: 1 | H29: голубой, красный, чёрный, жёлтый, зелёный, оранжевый, розовый, белый, желто-зеленый, коричнево-серый, коричневый, красно-черный, серый | I29: 2.1 | J29: ПВХ-пластикат маслобензостойкий | M29: -40 | N29: 105 | O29: 48 (ном.) / 1000 (испыт.) | Q29: 12 | R29: 38 | S29: 17.6 | U29: https://snabcable.ru/car/pvam-pvame-pvamde/pvam/ | V29: snabcable.ru; жила — медь многопроволочная (класс гибкости страницей не указан, по аналогии с сечениями 0,50/0,35 в базе — 5-й класс) — решено агентом — проверить. Объединены 3 цветовые позиции (голубой,красный,чёрный)
A30: Силиконовый провод 10AWG | B30: силиконовый | C30: генерик (китайское производство), prodiel.ru | D30: 6 | E30: 10 | F30: 1050×0,08 (луж. медь) | G30: 1 | H30: красный, чёрный | I30: 5.4 | J30: силиконовая резина (метилвинилполисилоксан) | M30: -60 | N30: 200 | O30: 300 | P30: 65 (длит.) / 140 (кратк.) | R30: 20 | S30: 188.5 | U30: https://prodiel.ru/provod/provod-gibkiy-v-silikone/silicon-10-awg/ | V30: rccopter.ru обзор + карточка товара prodiel.ru (provod-silikonoviy-10awg-6-mm-kv); реальное сечение 6мм2 отличается от теоретического AWG10 (5,26мм2) — решено агентом — проверить. Напряжение 300В по rccopter, у соседних сечений линейки продавец указывает 600В — расхождение не разрешено — решено агентом — проверить. Объединены 2 цветовые позиции (красный,чёрный)
A31: Силиконовый провод 12AWG | B31: силиконовый | C31: генерик (китайское производство), prodiel.ru | D31: 3.4 | E31: 12 | F31: 680×0,08 (луж. медь) | G31: 1 | H31: красный, чёрный | I31: 4.5 | J31: силиконовая резина (метилвинилполисилоксан + SiO2) | M31: -60 | N31: 200 | O31: 600 | P31: 30 | R31: 10 | S31: 201.5 | T31: Китай | U31: https://prodiel.ru/provod-gibkiy-medniy-luzheniy-awg-12-40-mm-kv-krasniy-100-m | V31: prodiel.ru карточки товара (awg-12-40-mm-kv, красный/чёрный); сопротивление 5,74 Ом/км при 20°C. Объединены 2 цветовые позиции
A32: Силиконовый провод 8AWG | B32: силиконовый | C32: генерик (китайское производство), prodiel.ru | D32: 8.25 | E32: 8 | F32: 1650×0,08 (луж. медь) | G32: 1 | H32: красный, чёрный | I32: 6 | J32: силиконовая резина (метилвинилполисилоксан) | M32: -60 | N32: 200 | O32: 600 | P32: 80 | R32: 8 | S32: 450.6 | U32: https://prodiel.ru/provod-gibkiy-medn-luzh-awg-8-83-mm-kv-krasniy-100-m | V32: prodiel.ru карточки товара (medn-luzh-awg-8-83-mm-kv); сопротивление 2,17 Ом/км при 20°C, медь 99,8%/луж. 0,2%. Объединены 2 цветовые позиции
A33: UL758 12AWG | B33: монтажный | C33: UL758 — номер стандарта AWM в целом, конкретный style не идентифицирован (см. также запись UL758 10AWG) | D33: 3.31 | E33: 12 | F33: 19×0,47 (луж. медь, по типовому стороннему даташиту) | G33: 1 | H33: black, red | I33: 3.94 | J33: ПВХ | M33: -20 | N33: 105 | O33: 600 | R33: 8 | S33: 100.8 | T33: Фраксис | V33: Ссылка покупателем не дана; сечение 3,31мм2 — по стандартной таблице AWG для 12AWG, не из даташита; жила/OD/температура — по типовому стороннему 12AWG hookup-wire datasheet (пример с digikey), не подтверждено для конкретного товара у Фраксис — решено агентом — проверить. Объединены 2 цветовые позиции (black,red)
A34: Силиконовый провод 18AWG | B34: силиконовый | C34: генерик (китайское производство), prodiel.ru | D34: 0.75 | E34: 18 | F34: 150×0,08 (луж. медь) | G34: 1 | H34: чёрный, красный | I34: 2.3 | J34: силиконовая резина (метилвинилполисилоксан) | M34: -60 | N34: 200 | O34: 600 | P34: 6 | R34: 13 | S34: 50 | U34: https://prodiel.ru/provod-gibkiy-medniy-luzheniy-awg-18-075-mm-kv-cherniy-305-m | V34: Покупатель указал как «UL758 18AWG», но по ссылке на prodiel.ru товар — силиконовый провод (метилвинилполисилоксан), а не даташит UL758 AWM; переименовано в «Силиконовый провод 18AWG» по фактическим характеристикам страницы — решено агентом — проверить. Сопротивление 24,47 Ом/км при 20°C, медь 99,8%/луж. 0,2%. Объединены 2 цветовые позиции (Black→чёрный, Red→красный)
A35: МГТФ 0,07 | B35: монтажный (термостойкий) | C35: ТУ 16-505.185-71 | D35: 0.07 | G35: 1 | H35: белый | I35: 0.75 | J35: фторопласт (сетчатая обмотка) | M35: -60 | N35: 220 | O35: 250 (AC, 5кГц) / 350 (DC) | Q35: 1.22 | R35: 6 | S35: 17.3 | U35: https://snabcable.ru/mounting/mgtf-mgtfe/mgtf/ | V35: chuvashkabel (через поиск), ТУ 16-505.185-71; OD 0,75мм, масса 1,22 кг/км для сечения 0,07мм2. Цена последней закупки указана 0,0 — похоже на ошибку данных (см. МГТФ 0,35 — 16,3) — решено агентом — проверить. Число проволок жилы страницей не уточнено
A36: МГТФ 0,35 | B36: монтажный (термостойкий) | C36: ТУ 16-505.185-71 | D36: 0.35 | G36: 1 | I36: 1.19 | J36: фторопласт (сетчатая обмотка) | M36: -60 | N36: 220 | O36: 250 (AC, 5кГц) / 350 (DC) | Q36: 4.25 | R36: 4 | S36: 16.3 | U36: https://snabcable.ru/mounting/mgtf-mgtfe/mgtf/ | V36: chuvashkabel (через поиск), ТУ 16-505.185-71; OD 1,19мм, масса 4,25 кг/км для сечения 0,35мм2. Число проволок жилы страницей не уточнено
A37: ШВПМ 2x0,5 | B37: аудио/сигнальный шнур | C37: ГОСТ 3578-005-39793330-2010 | D37: 0.5 | F37: 16×0,20 | G37: 2 | I37: 4,8×2,34 | J37: ПВХ | M37: -40 | N37: 70 | O37: 100 | Q37: 19.2 | R37: 4 | S37: 45.5 | U37: https://paritet.su/catalog/shvpm_dlya_audio/shvpm_2kh0_50_mm_kv/ | V37: paritet.su карточка товара; сопротивление жилы 39 Ом/км при 20°C. Экран страницей не упомянут (несмотря на категорию «для аудио») — решено агентом — проверить. Минимальная температура монтажа -15°C
A38: ПВАМ 2,5 | B38: силовой | C38: ТУ 16.К19-12-2003 | D38: 2.5 | G38: 1 | I38: 3 | J38: ПВХ-пластикат маслобензостойкий | M38: -40 | N38: 105 | O38: 48 (ном.) / 1000 (испыт.) | Q38: 28 | R38: 3 | S38: 0 | T38: Заказчик | U38: https://snabcable.ru/car/pvam-pvame-pvamde/pvam/ | V38: snabcable.ru; цена последней закупки указана 0,0 — вероятно ошибка данных (у других сечений ПВАМ цена 9–16) — решено агентом — проверить. Номинальное напряжение 48В принято по аналогии с другими сечениями серии, для 2,5мм2 отдельно страницей не подтверждено — решено агентом — проверить. Цвет не указан покупателем
A39: ПуГВ 1,0 | B39: монтажный (повышенной гибкости) | C39: ГОСТ 31947-2012, ТУ 16-705.501-2010 | D39: 1 | G39: 1 | H39: белый, жёлто-зелёный, синий | I39: 2.5 | J39: ПВХ-пластикат | M39: -50 | N39: 65 | O39: 450 | Q39: 16 | R39: 9 | S39: 18 | U39: https://snabcable.ru/mounting/mgtf-mgtfe/pv-3-pugv/ | V39: electro-mpo.ru (карточка жёлто-зелёный) + ruscable.ru (общий профиль ПуГВ); жила 5-го класса гибкости, страндинг страницей не указан — решено агентом — проверить. Цена последней закупки у цветов расходится (18,0–18,5) — взято модальное 18,0 — решено агентом — проверить. Объединены 3 цветовые позиции (белый,жёлто-зелёный,синий)
A40: FTP 2PR 24AWG CAT5e | B40: витая пара (LAN) | C40: REXANT, ТУ; категория 5e | E40: 24 | F40: многопроволочная (страндинг не уточнён) | G40: 4 | H40: серый | I40: 5 | J40: жилы — HDPE, оболочка — ПВХ 0,5мм | K40: фольга (FTP) | L40: 100 | M40: -40 | N40: 60 | R40: 3 | S40: 56 | U40: https://www.vseinstrumenti.ru/product/kabel-rexant-vitaya-para-ftp-2pr-24awg-cat5e-stranded-buhta-305-m-01-0125-1293812/ | V40: vseinstrumenti.ru карточка REXANT FTP 2PR 24AWG CAT5e; частотный диапазон 100МГц; 4 проводника (2 пары). Волновое сопротивление 100 Ом — по определению категории 5e, страницей отдельно не указано — решено агентом — проверить
...

Sheet БД.ОП-ТК
A1: КОД ОПЕРАЦИИ | B1: НАЗВАНИЕ | C1: ТИПОВЫЕ ДЕФЕКТЫ | D1: БЕЗОПАСНОСТЬ | E1: РЕВИЗИЯ | F1: ИЗМЕНЕНО | G1: КЕМ
A2: CUT_COAX+1strip | B2: Резка с разделкой | C2: ТИПОВЫЕ ДЕФЕКТЫ (Критерии отбраковки / NG) для резки и зачистки: Согласно IPC/WHMA-A-620F (класс 3) и КД, браком на данном этапе считаются: 1. Дефекты токопроводящей жилы (Самые критичные): Подрезка жил: Обрыв, глубокие надрезы или царапины на проволочках многопроволочной жилы (или на монолите) ножами станка. Приводит к занижению фактического сечения и перелому провода при вибрации. Распушение жил: Потеря исходной структуры скрутки жилы при стягивании изоляции. Распушенные проволочки не позволят качественно провести лужение или опрессовку (жилы не зайдут в терминал). Вытягивание жил: Нарушение шага скрутки жилы внутри провода из-за избыточного усилия стягивания изоляции (тупые ножи или неверный диаметр врезания). 2. Дефекты изоляции: Смятие изоляции: Профиль провода деформирован, сплющен или имеет глубокие следы (прокусы) от слишком сильного прижима подающих роликов станка. Рваный край изоляции: Срез неровный, имеет бахрому или заусенцы. Остатки изоляции: Изоляционная оболочка снята не полностью, на медных жилах остались фрагменты пластика, которые помешают электрическому контакту при опрессовке. 3. Отклонения геометрии: Длина зачистки вне допуска: Слишком короткая зачистка не обеспечит нужный вылет жил при опрессовке терминала, а слишком длинная приведет к оголению меди за пределами разъема (риск короткого замыкания). | D2: ВАЖНО! ТРЕБОВАНИЕ БЕЗОПАСНОСТИ: Все механические манипуляции по настройке, замене матриц, регулировке ножей и обслуживанию оборудования проводить исключительно в полностью обесточенном состоянии. В процессе работы использовать средства индивидуальной защиты (перчатки, защитные очки при пайке).
A3: CUT_COAX+2strip | B3: Резка с разделкой | C3: ТИПОВЫЕ ДЕФЕКТЫ (Критерии отбраковки / NG) для резки и зачистки: Согласно IPC/WHMA-A-620F (класс 3) и КД, браком на данном этапе считаются: 1. Дефекты токопроводящей жилы (Самые критичные): Подрезка жил: Обрыв, глубокие надрезы или царапины на проволочках многопроволочной жилы (или на монолите) ножами станка. Приводит к занижению фактического сечения и перелому провода при вибрации. Распушение жил: Потеря исходной структуры скрутки жилы при стягивании изоляции. Распушенные проволочки не позволят качественно провести лужение или опрессовку (жилы не зайдут в терминал). Вытягивание жил: Нарушение шага скрутки жилы внутри провода из-за избыточного усилия стягивания изоляции (тупые ножи или неверный диаметр врезания). 2. Дефекты изоляции: Смятие изоляции: Профиль провода деформирован, сплющен или имеет глубокие следы (прокусы) от слишком сильного прижима подающих роликов станка. Рваный край изоляции: Срез неровный, имеет бахрому или заусенцы. Остатки изоляции: Изоляционная оболочка снята не полностью, на медных жилах остались фрагменты пластика, которые помешают электрическому контакту при опрессовке. 3. Отклонения геометрии: Длина зачистки вне допуска: Слишком короткая зачистка не обеспечит нужный вылет жил при опрессовке терминала, а слишком длинная приведет к оголению меди за пределами разъема (риск короткого замыкания). | D3: ВАЖНО! ТРЕБОВАНИЕ БЕЗОПАСНОСТИ: Все механические манипуляции по настройке, замене матриц, регулировке ножей и обслуживанию оборудования проводить исключительно в полностью обесточенном состоянии. В процессе работы использовать средства индивидуальной защиты (перчатки, защитные очки при пайке).
A4: CUT_NEYLON | B4: Резка линейных материалов | C4: ТИПОВЫЕ ДЕФЕКТЫ (NG): распускание (расплетание) торца рукава (нет оплавления среза); пережим/деформация рукава; косой рез; несоответствие длины КД; чрезмерное оплавление (закрытие просвета). | D4: ВАЖНО! ТРЕБОВАНИЕ БЕЗОПАСНОСТИ: Все механические манипуляции по настройке, замене матриц, регулировке ножей и обслуживанию оборудования проводить исключительно в полностью обесточенном состоянии. В процессе работы использовать средства индивидуальной защиты (перчатки, защитные очки при пайке).
A5: CUT_TUT_long | B5: Резка линейных материалов | C5: ТИПОВЫЕ ДЕФЕКТЫ (NG): сплющивание (слипание стенок) трубки ТУТ; косой рез (неперпендикулярный); заусенцы/надрывы на торце; несоответствие длины КД; преждевременная усадка от нагрева. | D5: ВАЖНО! ТРЕБОВАНИЕ БЕЗОПАСНОСТИ: Все механические манипуляции по настройке, замене матриц, регулировке ножей и обслуживанию оборудования проводить исключительно в полностью обесточенном состоянии. В процессе работы использовать средства индивидуальной защиты (перчатки, защитные очки при пайке).
A6: CUT_TUT_short | B6: Резка | C6: ТИПОВЫЕ ДЕФЕКТЫ (Критерии отбраковки / NG) для резки ТУТ: В соответствии с требованиями к монтажу (опираясь на IPC/WHMA-A-620F по изоляционным материалам), отбраковке подлежат отрезки, имеющие следующие дефекты: 1. Дефекты кромок (Критично для ТУТ): Рваный край / Заусенцы: Неровный срез с бахромой (приводит к неравномерной усадке и риску пробоя изоляции). Продольные надрезы и микротрещины на торце: Недопустимы, так как при нагреве (усадке) трубка гарантированно порвется вдоль надреза. 2. Нарушение геометрии реза и профиля: Косой рез: Плоскость среза не перпендикулярна продольной оси трубки (угол отклонения превышает допустимый норматив, оголяя часть зоны, подлежащей изоляции). Сплющивание (слипание) трубки: Необратимая деформация профиля трубки механизмом подачи или тупым ножом, препятствующая свободному надеванию ТУТ на провод/контакт. 3. Габаритные отклонения: Длина вне допуска: Отрезок короче или длиннее заданного чертежом размера. (Слишком короткая ТУТ не обеспечит должного перекрытия изоляции, слишком длинная может налезть на контактную зону). | D6: ВАЖНО! ТРЕБОВАНИЕ БЕЗОПАСНОСТИ: Все механические манипуляции по настройке, замене матриц, регулировке ножей и обслуживанию оборудования проводить исключительно в полностью обесточенном состоянии. В процессе работы использовать средства индивидуальной защиты (перчатки, защитные очки при пайке).
A7: CUT_WIRE+1crimp | B7: Автомат резка + опрессовка | C7: ТИПОВЫЕ ДЕФЕКТЫ (Критерии отбраковки / NG) для резки и зачистки: Согласно IPC/WHMA-A-620F (класс 3) и КД, браком на данном этапе считаются: 1. Дефекты токопроводящей жилы (Самые критичные): Подрезка жил: Обрыв, глубокие надрезы или царапины на проволочках многопроволочной жилы (или на монолите) ножами станка. Приводит к занижению фактического сечения и перелому провода при вибрации. Распушение жил: Потеря исходной структуры скрутки жилы при стягивании изоляции. Распушенные проволочки не позволят качественно провести лужение или опрессовку (жилы не зайдут в терминал). Вытягивание жил: Нарушение шага скрутки жилы внутри провода из-за избыточного усилия стягивания изоляции (тупые ножи или неверный диаметр врезания). 2. Дефекты изоляции: Смятие изоляции: Профиль провода деформирован, сплющен или имеет глубокие следы (прокусы) от слишком сильного прижима подающих роликов станка. Рваный край изоляции: Срез неровный, имеет бахрому или заусенцы. Остатки изоляции: Изоляционная оболочка снята не полностью, на медных жилах остались фрагменты пластика, которые помешают электрическому контакту при опрессовке. 3. Отклонения геометрии: Длина зачистки вне допуска: Слишком короткая зачистка не обеспечит нужный вылет жил при опрессовке терминала, а слишком длинная приведет к оголению меди за пределами разъема (риск короткого замыкания). | D7: ВАЖНО! ТРЕБОВАНИЕ БЕЗОПАСНОСТИ: Все механические манипуляции по настройке, замене матриц, регулировке ножей и обслуживанию оборудования проводить исключительно в полностью обесточенном состоянии. В процессе работы использовать средства индивидуальной защиты (перчатки, защитные очки при пайке).
A8: CUT_WIRE+1strip | B8: Резка с разделкой | C8: ТИПОВЫЕ ДЕФЕКТЫ (Критерии отбраковки / NG) для резки и зачистки: Согласно IPC/WHMA-A-620F (класс 3) и КД, браком на данном этапе считаются: 1. Дефекты токопроводящей жилы (Самые критичные): Подрезка жил: Обрыв, глубокие надрезы или царапины на проволочках многопроволочной жилы (или на монолите) ножами станка. Приводит к занижению фактического сечения и перелому провода при вибрации. Распушение жил: Потеря исходной структуры скрутки жилы при стягивании изоляции. Распушенные проволочки не позволят качественно провести лужение или опрессовку (жилы не зайдут в терминал). Вытягивание жил: Нарушение шага скрутки жилы внутри провода из-за избыточного усилия стягивания изоляции (тупые ножи или неверный диаметр врезания). 2. Дефекты изоляции: Смятие изоляции: Профиль провода деформирован, сплющен или имеет глубокие следы (прокусы) от слишком сильного прижима подающих роликов станка. Рваный край изоляции: Срез неровный, имеет бахрому или заусенцы. Остатки изоляции: Изоляционная оболочка снята не полностью, на медных жилах остались фрагменты пластика, которые помешают электрическому контакту при опрессовке. 3. Отклонения геометрии: Длина зачистки вне допуска: Слишком короткая зачистка не обеспечит нужный вылет жил при опрессовке терминала, а слишком длинная приведет к оголению меди за пределами разъема (риск короткого замыкания). | D8: ВАЖНО! ТРЕБОВАНИЕ БЕЗОПАСНОСТИ: Все механические манипуляции по настройке, замене матриц, регулировке ножей и обслуживанию оборудования проводить исключительно в полностью обесточенном состоянии. В процессе работы использовать средства индивидуальной защиты (перчатки, защитные очки при пайке).
A9: CUT_WIRE+1strip+1mark | B9: Резка с разделкой+ маркировка | C9: ТИПОВЫЕ ДЕФЕКТЫ (Критерии отбраковки / NG) для резки и зачистки: Согласно IPC/WHMA-A-620F (класс 3) и КД, браком на данном этапе считаются: 1. Дефекты токопроводящей жилы (Самые критичные): Подрезка жил: Обрыв, глубокие надрезы или царапины на проволочках многопроволочной жилы (или на монолите) ножами станка. Приводит к занижению фактического сечения и перелому провода при вибрации. Распушение жил: Потеря исходной структуры скрутки жилы при стягивании изоляции. Распушенные проволочки не позволят качественно провести лужение или опрессовку (жилы не зайдут в терминал). Вытягивание жил: Нарушение шага скрутки жилы внутри провода из-за избыточного усилия стягивания изоляции (тупые ножи или неверный диаметр врезания). 2. Дефекты изоляции: Смятие изоляции: Профиль провода деформирован, сплющен или имеет глубокие следы (прокусы) от слишком сильного прижима подающих роликов станка. Рваный край изоляции: Срез неровный, имеет бахрому или заусенцы. Остатки изоляции: Изоляционная оболочка снята не полностью, на медных жилах остались фрагменты пластика, которые помешают электрическому контакту при опрессовке. 3. Отклонения геометрии: Длина зачистки вне допуска: Слишком короткая зачистка не обеспечит нужный вылет жил при опрессовке терминала, а слишком длинная приведет к оголению меди за пределами разъема (риск короткого замыкания). | D9: ВАЖНО! ТРЕБОВАНИЕ БЕЗОПАСНОСТИ: Все механические манипуляции по настройке, замене матриц, регулировке ножей и обслуживанию оборудования проводить исключительно в полностью обесточенном состоянии. В процессе работы использовать средства индивидуальной защиты (перчатки, защитные очки при пайке).
